 * Serving Flask app "run" (lazy loading)
 * Environment: production
   WARNING: This is a development server. Do not use it in a production deployment.
   Use a production WSGI server instead.
 * Debug mode: on
Traceback (most recent call last):
  File "/home/zawar/Workspace/jwtFlask/myvenv/lib/python3.6/site-packages/flask/app.py", line 2463, in __call__
    return self.wsgi_app(environ, start_response)
  File "/home/zawar/Workspace/jwtFlask/myvenv/lib/python3.6/site-packages/flask/app.py", line 2449, in wsgi_app
    response = self.handle_exception(e)
  File "/home/zawar/Workspace/jwtFlask/myvenv/lib/python3.6/site-packages/flask_restful/__init__.py", line 269, in error_router
    return original_handler(e)
  File "/home/zawar/Workspace/jwtFlask/myvenv/lib/python3.6/site-packages/flask/app.py", line 1866, in handle_exception
    reraise(exc_type, exc_value, tb)
  File "/home/zawar/Workspace/jwtFlask/myvenv/lib/python3.6/site-packages/flask/_compat.py", line 38, in reraise
    raise value.with_traceback(tb)
  File "/home/zawar/Workspace/jwtFlask/myvenv/lib/python3.6/site-packages/flask/app.py", line 2446, in wsgi_app
    response = self.full_dispatch_request()
  File "/home/zawar/Workspace/jwtFlask/myvenv/lib/python3.6/site-packages/flask/app.py", line 1951, in full_dispatch_request
    rv = self.handle_user_exception(e)
  File "/home/zawar/Workspace/jwtFlask/myvenv/lib/python3.6/site-packages/flask_restful/__init__.py", line 269, in error_router
    return original_handler(e)
  File "/home/zawar/Workspace/jwtFlask/myvenv/lib/python3.6/site-packages/flask/app.py", line 1820, in handle_user_exception
    reraise(exc_type, exc_value, tb)
  File "/home/zawar/Workspace/jwtFlask/myvenv/lib/python3.6/site-packages/flask/_compat.py", line 38, in reraise
    raise value.with_traceback(tb)
  File "/home/zawar/Workspace/jwtFlask/myvenv/lib/python3.6/site-packages/flask/app.py", line 1949, in full_dispatch_request
    rv = self.dispatch_request()
  File "/home/zawar/Workspace/jwtFlask/myvenv/lib/python3.6/site-packages/flask/app.py", line 1935, in dispatch_request
    return self.view_functions[rule.endpoint](**req.view_args)
  File "/home/zawar/Workspace/jwtFlask/myvenv/lib/python3.6/site-packages/flask_restful/__init__.py", line 458, in wrapper
    resp = resource(*args, **kwargs)
  File "/home/zawar/Workspace/jwtFlask/myvenv/lib/python3.6/site-packages/flask/views.py", line 89, in view
    return self.dispatch_request(*args, **kwargs)
  File "/home/zawar/Workspace/jwtFlask/myvenv/lib/python3.6/site-packages/flask_restful/__init__.py", line 573, in dispatch_request
    resp = meth(*args, **kwargs)
  File "/home/zawar/Workspace/jwtFlask/services/resources.py", line 23, in post
    data_id=UserRepo().signup_user(data['dsgsdg'])
KeyError: 'dsgsdg'
Traceback (most recent call last):
  File "/home/zawar/Workspace/jwtFlask/myvenv/lib/python3.6/site-packages/flask/app.py", line 2463, in __call__
    return self.wsgi_app(environ, start_response)
  File "/home/zawar/Workspace/jwtFlask/myvenv/lib/python3.6/site-packages/flask/app.py", line 2449, in wsgi_app
    response = self.handle_exception(e)
  File "/home/zawar/Workspace/jwtFlask/myvenv/lib/python3.6/site-packages/flask_restful/__init__.py", line 269, in error_router
    return original_handler(e)
  File "/home/zawar/Workspace/jwtFlask/myvenv/lib/python3.6/site-packages/flask/app.py", line 1866, in handle_exception
    reraise(exc_type, exc_value, tb)
  File "/home/zawar/Workspace/jwtFlask/myvenv/lib/python3.6/site-packages/flask/_compat.py", line 38, in reraise
    raise value.with_traceback(tb)
  File "/home/zawar/Workspace/jwtFlask/myvenv/lib/python3.6/site-packages/flask/app.py", line 2446, in wsgi_app
    response = self.full_dispatch_request()
  File "/home/zawar/Workspace/jwtFlask/myvenv/lib/python3.6/site-packages/flask/app.py", line 1951, in full_dispatch_request
    rv = self.handle_user_exception(e)
  File "/home/zawar/Workspace/jwtFlask/myvenv/lib/python3.6/site-packages/flask_restful/__init__.py", line 269, in error_router
    return original_handler(e)
  File "/home/zawar/Workspace/jwtFlask/myvenv/lib/python3.6/site-packages/flask/app.py", line 1820, in handle_user_exception
    reraise(exc_type, exc_value, tb)
  File "/home/zawar/Workspace/jwtFlask/myvenv/lib/python3.6/site-packages/flask/_compat.py", line 38, in reraise
    raise value.with_traceback(tb)
  File "/home/zawar/Workspace/jwtFlask/myvenv/lib/python3.6/site-packages/flask/app.py", line 1949, in full_dispatch_request
    rv = self.dispatch_request()
  File "/home/zawar/Workspace/jwtFlask/myvenv/lib/python3.6/site-packages/flask/app.py", line 1935, in dispatch_request
    return self.view_functions[rule.endpoint](**req.view_args)
  File "/home/zawar/Workspace/jwtFlask/myvenv/lib/python3.6/site-packages/flask_restful/__init__.py", line 458, in wrapper
    resp = resource(*args, **kwargs)
  File "/home/zawar/Workspace/jwtFlask/myvenv/lib/python3.6/site-packages/flask/views.py", line 89, in view
    return self.dispatch_request(*args, **kwargs)
  File "/home/zawar/Workspace/jwtFlask/myvenv/lib/python3.6/site-packages/flask_restful/__init__.py", line 573, in dispatch_request
    resp = meth(*args, **kwargs)
  File "/home/zawar/Workspace/jwtFlask/services/resources.py", line 23, in post
    data_id=UserRepo().signup_user(data['dsgsdg'])
KeyError: 'dsgsdg'
Traceback (most recent call last):
  File "/home/zawar/Workspace/jwtFlask/myvenv/lib/python3.6/site-packages/flask/app.py", line 2463, in __call__
    return self.wsgi_app(environ, start_response)
  File "/home/zawar/Workspace/jwtFlask/myvenv/lib/python3.6/site-packages/flask/app.py", line 2449, in wsgi_app
    response = self.handle_exception(e)
  File "/home/zawar/Workspace/jwtFlask/myvenv/lib/python3.6/site-packages/flask_restful/__init__.py", line 269, in error_router
    return original_handler(e)
  File "/home/zawar/Workspace/jwtFlask/myvenv/lib/python3.6/site-packages/flask/app.py", line 1866, in handle_exception
    reraise(exc_type, exc_value, tb)
  File "/home/zawar/Workspace/jwtFlask/myvenv/lib/python3.6/site-packages/flask/_compat.py", line 38, in reraise
    raise value.with_traceback(tb)
  File "/home/zawar/Workspace/jwtFlask/myvenv/lib/python3.6/site-packages/flask/app.py", line 2446, in wsgi_app
    response = self.full_dispatch_request()
  File "/home/zawar/Workspace/jwtFlask/myvenv/lib/python3.6/site-packages/flask/app.py", line 1951, in full_dispatch_request
    rv = self.handle_user_exception(e)
  File "/home/zawar/Workspace/jwtFlask/myvenv/lib/python3.6/site-packages/flask_restful/__init__.py", line 269, in error_router
    return original_handler(e)
  File "/home/zawar/Workspace/jwtFlask/myvenv/lib/python3.6/site-packages/flask/app.py", line 1820, in handle_user_exception
    reraise(exc_type, exc_value, tb)
  File "/home/zawar/Workspace/jwtFlask/myvenv/lib/python3.6/site-packages/flask/_compat.py", line 38, in reraise
    raise value.with_traceback(tb)
  File "/home/zawar/Workspace/jwtFlask/myvenv/lib/python3.6/site-packages/flask/app.py", line 1949, in full_dispatch_request
    rv = self.dispatch_request()
  File "/home/zawar/Workspace/jwtFlask/myvenv/lib/python3.6/site-packages/flask/app.py", line 1935, in dispatch_request
    return self.view_functions[rule.endpoint](**req.view_args)
  File "/home/zawar/Workspace/jwtFlask/myvenv/lib/python3.6/site-packages/flask_restful/__init__.py", line 458, in wrapper
    resp = resource(*args, **kwargs)
  File "/home/zawar/Workspace/jwtFlask/myvenv/lib/python3.6/site-packages/flask/views.py", line 89, in view
    return self.dispatch_request(*args, **kwargs)
  File "/home/zawar/Workspace/jwtFlask/myvenv/lib/python3.6/site-packages/flask_restful/__init__.py", line 573, in dispatch_request
    resp = meth(*args, **kwargs)
  File "/home/zawar/Workspace/jwtFlask/services/resources.py", line 23, in post
    data_id=UserRepo().signup_user(data['dsgsdg'])
KeyError: 'dsgsdg'
Traceback (most recent call last):
  File "/home/zawar/Workspace/jwtFlask/myvenv/lib/python3.6/site-packages/flask/app.py", line 2463, in __call__
    return self.wsgi_app(environ, start_response)
  File "/home/zawar/Workspace/jwtFlask/myvenv/lib/python3.6/site-packages/flask/app.py", line 2449, in wsgi_app
    response = self.handle_exception(e)
  File "/home/zawar/Workspace/jwtFlask/myvenv/lib/python3.6/site-packages/flask_restful/__init__.py", line 269, in error_router
    return original_handler(e)
  File "/home/zawar/Workspace/jwtFlask/myvenv/lib/python3.6/site-packages/flask/app.py", line 1866, in handle_exception
    reraise(exc_type, exc_value, tb)
  File "/home/zawar/Workspace/jwtFlask/myvenv/lib/python3.6/site-packages/flask/_compat.py", line 38, in reraise
    raise value.with_traceback(tb)
  File "/home/zawar/Workspace/jwtFlask/myvenv/lib/python3.6/site-packages/flask/app.py", line 2446, in wsgi_app
    response = self.full_dispatch_request()
  File "/home/zawar/Workspace/jwtFlask/myvenv/lib/python3.6/site-packages/flask/app.py", line 1951, in full_dispatch_request
    rv = self.handle_user_exception(e)
  File "/home/zawar/Workspace/jwtFlask/myvenv/lib/python3.6/site-packages/flask_restful/__init__.py", line 269, in error_router
    return original_handler(e)
  File "/home/zawar/Workspace/jwtFlask/myvenv/lib/python3.6/site-packages/flask/app.py", line 1820, in handle_user_exception
    reraise(exc_type, exc_value, tb)
  File "/home/zawar/Workspace/jwtFlask/myvenv/lib/python3.6/site-packages/flask/_compat.py", line 38, in reraise
    raise value.with_traceback(tb)
  File "/home/zawar/Workspace/jwtFlask/myvenv/lib/python3.6/site-packages/flask/app.py", line 1949, in full_dispatch_request
    rv = self.dispatch_request()
  File "/home/zawar/Workspace/jwtFlask/myvenv/lib/python3.6/site-packages/flask/app.py", line 1935, in dispatch_request
    return self.view_functions[rule.endpoint](**req.view_args)
  File "/home/zawar/Workspace/jwtFlask/myvenv/lib/python3.6/site-packages/flask_restful/__init__.py", line 458, in wrapper
    resp = resource(*args, **kwargs)
  File "/home/zawar/Workspace/jwtFlask/myvenv/lib/python3.6/site-packages/flask/views.py", line 89, in view
    return self.dispatch_request(*args, **kwargs)
  File "/home/zawar/Workspace/jwtFlask/myvenv/lib/python3.6/site-packages/flask_restful/__init__.py", line 573, in dispatch_request
    resp = meth(*args, **kwargs)
  File "/home/zawar/Workspace/jwtFlask/services/resources.py", line 23, in post
    data_id=UserRepo().signup_user(data['dsgsdg'])
KeyError: 'dsgsdg'
signup user
Traceback (most recent call last):
  File "/home/zawar/Workspace/jwtFlask/myvenv/lib/python3.6/site-packages/flask/app.py", line 2463, in __call__
    return self.wsgi_app(environ, start_response)
  File "/home/zawar/Workspace/jwtFlask/myvenv/lib/python3.6/site-packages/flask/app.py", line 2449, in wsgi_app
    response = self.handle_exception(e)
  File "/home/zawar/Workspace/jwtFlask/myvenv/lib/python3.6/site-packages/flask_restful/__init__.py", line 269, in error_router
    return original_handler(e)
  File "/home/zawar/Workspace/jwtFlask/myvenv/lib/python3.6/site-packages/flask/app.py", line 1866, in handle_exception
    reraise(exc_type, exc_value, tb)
  File "/home/zawar/Workspace/jwtFlask/myvenv/lib/python3.6/site-packages/flask/_compat.py", line 38, in reraise
    raise value.with_traceback(tb)
  File "/home/zawar/Workspace/jwtFlask/myvenv/lib/python3.6/site-packages/flask/app.py", line 2446, in wsgi_app
    response = self.full_dispatch_request()
  File "/home/zawar/Workspace/jwtFlask/myvenv/lib/python3.6/site-packages/flask/app.py", line 1951, in full_dispatch_request
    rv = self.handle_user_exception(e)
  File "/home/zawar/Workspace/jwtFlask/myvenv/lib/python3.6/site-packages/flask_restful/__init__.py", line 269, in error_router
    return original_handler(e)
  File "/home/zawar/Workspace/jwtFlask/myvenv/lib/python3.6/site-packages/flask/app.py", line 1820, in handle_user_exception
    reraise(exc_type, exc_value, tb)
  File "/home/zawar/Workspace/jwtFlask/myvenv/lib/python3.6/site-packages/flask/_compat.py", line 38, in reraise
    raise value.with_traceback(tb)
  File "/home/zawar/Workspace/jwtFlask/myvenv/lib/python3.6/site-packages/flask/app.py", line 1949, in full_dispatch_request
    rv = self.dispatch_request()
  File "/home/zawar/Workspace/jwtFlask/myvenv/lib/python3.6/site-packages/flask/app.py", line 1935, in dispatch_request
    return self.view_functions[rule.endpoint](**req.view_args)
  File "/home/zawar/Workspace/jwtFlask/myvenv/lib/python3.6/site-packages/flask_restful/__init__.py", line 458, in wrapper
    resp = resource(*args, **kwargs)
  File "/home/zawar/Workspace/jwtFlask/myvenv/lib/python3.6/site-packages/flask/views.py", line 89, in view
    return self.dispatch_request(*args, **kwargs)
  File "/home/zawar/Workspace/jwtFlask/myvenv/lib/python3.6/site-packages/flask_restful/__init__.py", line 573, in dispatch_request
    resp = meth(*args, **kwargs)
  File "/home/zawar/Workspace/jwtFlask/services/resources.py", line 28, in post
    response={'message':'User created {'.format(data['username']),
ValueError: Single '{' encountered in format string
signup user
Traceback (most recent call last):
  File "/home/zawar/Workspace/jwtFlask/myvenv/lib/python3.6/site-packages/flask/app.py", line 2463, in __call__
    return self.wsgi_app(environ, start_response)
  File "/home/zawar/Workspace/jwtFlask/myvenv/lib/python3.6/site-packages/flask/app.py", line 2449, in wsgi_app
    response = self.handle_exception(e)
  File "/home/zawar/Workspace/jwtFlask/myvenv/lib/python3.6/site-packages/flask_restful/__init__.py", line 269, in error_router
    return original_handler(e)
  File "/home/zawar/Workspace/jwtFlask/myvenv/lib/python3.6/site-packages/flask/app.py", line 1866, in handle_exception
    reraise(exc_type, exc_value, tb)
  File "/home/zawar/Workspace/jwtFlask/myvenv/lib/python3.6/site-packages/flask/_compat.py", line 38, in reraise
    raise value.with_traceback(tb)
  File "/home/zawar/Workspace/jwtFlask/myvenv/lib/python3.6/site-packages/flask/app.py", line 2446, in wsgi_app
    response = self.full_dispatch_request()
  File "/home/zawar/Workspace/jwtFlask/myvenv/lib/python3.6/site-packages/flask/app.py", line 1951, in full_dispatch_request
    rv = self.handle_user_exception(e)
  File "/home/zawar/Workspace/jwtFlask/myvenv/lib/python3.6/site-packages/flask_restful/__init__.py", line 269, in error_router
    return original_handler(e)
  File "/home/zawar/Workspace/jwtFlask/myvenv/lib/python3.6/site-packages/flask/app.py", line 1820, in handle_user_exception
    reraise(exc_type, exc_value, tb)
  File "/home/zawar/Workspace/jwtFlask/myvenv/lib/python3.6/site-packages/flask/_compat.py", line 38, in reraise
    raise value.with_traceback(tb)
  File "/home/zawar/Workspace/jwtFlask/myvenv/lib/python3.6/site-packages/flask/app.py", line 1949, in full_dispatch_request
    rv = self.dispatch_request()
  File "/home/zawar/Workspace/jwtFlask/myvenv/lib/python3.6/site-packages/flask/app.py", line 1935, in dispatch_request
    return self.view_functions[rule.endpoint](**req.view_args)
  File "/home/zawar/Workspace/jwtFlask/myvenv/lib/python3.6/site-packages/flask_restful/__init__.py", line 458, in wrapper
    resp = resource(*args, **kwargs)
  File "/home/zawar/Workspace/jwtFlask/myvenv/lib/python3.6/site-packages/flask/views.py", line 89, in view
    return self.dispatch_request(*args, **kwargs)
  File "/home/zawar/Workspace/jwtFlask/myvenv/lib/python3.6/site-packages/flask_restful/__init__.py", line 573, in dispatch_request
    resp = meth(*args, **kwargs)
  File "/home/zawar/Workspace/jwtFlask/services/resources.py", line 28, in post
    response={'message':'User created {'.format(data['username']),
ValueError: Single '{' encountered in format string
signup user
Traceback (most recent call last):
  File "/home/zawar/Workspace/jwtFlask/myvenv/lib/python3.6/site-packages/flask/app.py", line 2463, in __call__
    return self.wsgi_app(environ, start_response)
  File "/home/zawar/Workspace/jwtFlask/myvenv/lib/python3.6/site-packages/flask/app.py", line 2449, in wsgi_app
    response = self.handle_exception(e)
  File "/home/zawar/Workspace/jwtFlask/myvenv/lib/python3.6/site-packages/flask_restful/__init__.py", line 269, in error_router
    return original_handler(e)
  File "/home/zawar/Workspace/jwtFlask/myvenv/lib/python3.6/site-packages/flask/app.py", line 1866, in handle_exception
    reraise(exc_type, exc_value, tb)
  File "/home/zawar/Workspace/jwtFlask/myvenv/lib/python3.6/site-packages/flask/_compat.py", line 38, in reraise
    raise value.with_traceback(tb)
  File "/home/zawar/Workspace/jwtFlask/myvenv/lib/python3.6/site-packages/flask/app.py", line 2446, in wsgi_app
    response = self.full_dispatch_request()
  File "/home/zawar/Workspace/jwtFlask/myvenv/lib/python3.6/site-packages/flask/app.py", line 1951, in full_dispatch_request
    rv = self.handle_user_exception(e)
  File "/home/zawar/Workspace/jwtFlask/myvenv/lib/python3.6/site-packages/flask_restful/__init__.py", line 269, in error_router
    return original_handler(e)
  File "/home/zawar/Workspace/jwtFlask/myvenv/lib/python3.6/site-packages/flask/app.py", line 1820, in handle_user_exception
    reraise(exc_type, exc_value, tb)
  File "/home/zawar/Workspace/jwtFlask/myvenv/lib/python3.6/site-packages/flask/_compat.py", line 38, in reraise
    raise value.with_traceback(tb)
  File "/home/zawar/Workspace/jwtFlask/myvenv/lib/python3.6/site-packages/flask/app.py", line 1949, in full_dispatch_request
    rv = self.dispatch_request()
  File "/home/zawar/Workspace/jwtFlask/myvenv/lib/python3.6/site-packages/flask/app.py", line 1935, in dispatch_request
    return self.view_functions[rule.endpoint](**req.view_args)
  File "/home/zawar/Workspace/jwtFlask/myvenv/lib/python3.6/site-packages/flask_restful/__init__.py", line 458, in wrapper
    resp = resource(*args, **kwargs)
  File "/home/zawar/Workspace/jwtFlask/myvenv/lib/python3.6/site-packages/flask/views.py", line 89, in view
    return self.dispatch_request(*args, **kwargs)
  File "/home/zawar/Workspace/jwtFlask/myvenv/lib/python3.6/site-packages/flask_restful/__init__.py", line 573, in dispatch_request
    resp = meth(*args, **kwargs)
  File "/home/zawar/Workspace/jwtFlask/services/resources.py", line 28, in post
    response={'message':'User created {'.format(data['username']),
ValueError: Single '{' encountered in format string
signup user
Traceback (most recent call last):
  File "/home/zawar/Workspace/jwtFlask/myvenv/lib/python3.6/site-packages/flask/app.py", line 2463, in __call__
    return self.wsgi_app(environ, start_response)
  File "/home/zawar/Workspace/jwtFlask/myvenv/lib/python3.6/site-packages/flask/app.py", line 2449, in wsgi_app
    response = self.handle_exception(e)
  File "/home/zawar/Workspace/jwtFlask/myvenv/lib/python3.6/site-packages/flask_restful/__init__.py", line 269, in error_router
    return original_handler(e)
  File "/home/zawar/Workspace/jwtFlask/myvenv/lib/python3.6/site-packages/flask/app.py", line 1866, in handle_exception
    reraise(exc_type, exc_value, tb)
  File "/home/zawar/Workspace/jwtFlask/myvenv/lib/python3.6/site-packages/flask/_compat.py", line 38, in reraise
    raise value.with_traceback(tb)
  File "/home/zawar/Workspace/jwtFlask/myvenv/lib/python3.6/site-packages/flask/app.py", line 2446, in wsgi_app
    response = self.full_dispatch_request()
  File "/home/zawar/Workspace/jwtFlask/myvenv/lib/python3.6/site-packages/flask/app.py", line 1951, in full_dispatch_request
    rv = self.handle_user_exception(e)
  File "/home/zawar/Workspace/jwtFlask/myvenv/lib/python3.6/site-packages/flask_restful/__init__.py", line 269, in error_router
    return original_handler(e)
  File "/home/zawar/Workspace/jwtFlask/myvenv/lib/python3.6/site-packages/flask/app.py", line 1820, in handle_user_exception
    reraise(exc_type, exc_value, tb)
  File "/home/zawar/Workspace/jwtFlask/myvenv/lib/python3.6/site-packages/flask/_compat.py", line 38, in reraise
    raise value.with_traceback(tb)
  File "/home/zawar/Workspace/jwtFlask/myvenv/lib/python3.6/site-packages/flask/app.py", line 1949, in full_dispatch_request
    rv = self.dispatch_request()
  File "/home/zawar/Workspace/jwtFlask/myvenv/lib/python3.6/site-packages/flask/app.py", line 1935, in dispatch_request
    return self.view_functions[rule.endpoint](**req.view_args)
  File "/home/zawar/Workspace/jwtFlask/myvenv/lib/python3.6/site-packages/flask_restful/__init__.py", line 458, in wrapper
    resp = resource(*args, **kwargs)
  File "/home/zawar/Workspace/jwtFlask/myvenv/lib/python3.6/site-packages/flask/views.py", line 89, in view
    return self.dispatch_request(*args, **kwargs)
  File "/home/zawar/Workspace/jwtFlask/myvenv/lib/python3.6/site-packages/flask_restful/__init__.py", line 573, in dispatch_request
    resp = meth(*args, **kwargs)
  File "/home/zawar/Workspace/jwtFlask/services/resources.py", line 28, in post
    response={'message':'User created {'.format(data['username']),
ValueError: Single '{' encountered in format string
signup user
Traceback (most recent call last):
  File "/home/zawar/Workspace/jwtFlask/myvenv/lib/python3.6/site-packages/flask/app.py", line 2463, in __call__
    return self.wsgi_app(environ, start_response)
  File "/home/zawar/Workspace/jwtFlask/myvenv/lib/python3.6/site-packages/flask/app.py", line 2449, in wsgi_app
    response = self.handle_exception(e)
  File "/home/zawar/Workspace/jwtFlask/myvenv/lib/python3.6/site-packages/flask_restful/__init__.py", line 269, in error_router
    return original_handler(e)
  File "/home/zawar/Workspace/jwtFlask/myvenv/lib/python3.6/site-packages/flask/app.py", line 1866, in handle_exception
    reraise(exc_type, exc_value, tb)
  File "/home/zawar/Workspace/jwtFlask/myvenv/lib/python3.6/site-packages/flask/_compat.py", line 38, in reraise
    raise value.with_traceback(tb)
  File "/home/zawar/Workspace/jwtFlask/myvenv/lib/python3.6/site-packages/flask/app.py", line 2446, in wsgi_app
    response = self.full_dispatch_request()
  File "/home/zawar/Workspace/jwtFlask/myvenv/lib/python3.6/site-packages/flask/app.py", line 1951, in full_dispatch_request
    rv = self.handle_user_exception(e)
  File "/home/zawar/Workspace/jwtFlask/myvenv/lib/python3.6/site-packages/flask_restful/__init__.py", line 269, in error_router
    return original_handler(e)
  File "/home/zawar/Workspace/jwtFlask/myvenv/lib/python3.6/site-packages/flask/app.py", line 1820, in handle_user_exception
    reraise(exc_type, exc_value, tb)
  File "/home/zawar/Workspace/jwtFlask/myvenv/lib/python3.6/site-packages/flask/_compat.py", line 38, in reraise
    raise value.with_traceback(tb)
  File "/home/zawar/Workspace/jwtFlask/myvenv/lib/python3.6/site-packages/flask/app.py", line 1949, in full_dispatch_request
    rv = self.dispatch_request()
  File "/home/zawar/Workspace/jwtFlask/myvenv/lib/python3.6/site-packages/flask/app.py", line 1935, in dispatch_request
    return self.view_functions[rule.endpoint](**req.view_args)
  File "/home/zawar/Workspace/jwtFlask/myvenv/lib/python3.6/site-packages/flask_restful/__init__.py", line 458, in wrapper
    resp = resource(*args, **kwargs)
  File "/home/zawar/Workspace/jwtFlask/myvenv/lib/python3.6/site-packages/flask/views.py", line 89, in view
    return self.dispatch_request(*args, **kwargs)
  File "/home/zawar/Workspace/jwtFlask/myvenv/lib/python3.6/site-packages/flask_restful/__init__.py", line 573, in dispatch_request
    resp = meth(*args, **kwargs)
  File "/home/zawar/Workspace/jwtFlask/services/resources.py", line 28, in post
    response={'message':'User created {'.format(data['username']),
ValueError: Single '{' encountered in format string
signup user
Traceback (most recent call last):
  File "/home/zawar/Workspace/jwtFlask/myvenv/lib/python3.6/site-packages/flask/app.py", line 2463, in __call__
    return self.wsgi_app(environ, start_response)
  File "/home/zawar/Workspace/jwtFlask/myvenv/lib/python3.6/site-packages/flask/app.py", line 2449, in wsgi_app
    response = self.handle_exception(e)
  File "/home/zawar/Workspace/jwtFlask/myvenv/lib/python3.6/site-packages/flask_restful/__init__.py", line 269, in error_router
    return original_handler(e)
  File "/home/zawar/Workspace/jwtFlask/myvenv/lib/python3.6/site-packages/flask/app.py", line 1866, in handle_exception
    reraise(exc_type, exc_value, tb)
  File "/home/zawar/Workspace/jwtFlask/myvenv/lib/python3.6/site-packages/flask/_compat.py", line 38, in reraise
    raise value.with_traceback(tb)
  File "/home/zawar/Workspace/jwtFlask/myvenv/lib/python3.6/site-packages/flask/app.py", line 2446, in wsgi_app
    response = self.full_dispatch_request()
  File "/home/zawar/Workspace/jwtFlask/myvenv/lib/python3.6/site-packages/flask/app.py", line 1951, in full_dispatch_request
    rv = self.handle_user_exception(e)
  File "/home/zawar/Workspace/jwtFlask/myvenv/lib/python3.6/site-packages/flask_restful/__init__.py", line 269, in error_router
    return original_handler(e)
  File "/home/zawar/Workspace/jwtFlask/myvenv/lib/python3.6/site-packages/flask/app.py", line 1820, in handle_user_exception
    reraise(exc_type, exc_value, tb)
  File "/home/zawar/Workspace/jwtFlask/myvenv/lib/python3.6/site-packages/flask/_compat.py", line 38, in reraise
    raise value.with_traceback(tb)
  File "/home/zawar/Workspace/jwtFlask/myvenv/lib/python3.6/site-packages/flask/app.py", line 1949, in full_dispatch_request
    rv = self.dispatch_request()
  File "/home/zawar/Workspace/jwtFlask/myvenv/lib/python3.6/site-packages/flask/app.py", line 1935, in dispatch_request
    return self.view_functions[rule.endpoint](**req.view_args)
  File "/home/zawar/Workspace/jwtFlask/myvenv/lib/python3.6/site-packages/flask_restful/__init__.py", line 458, in wrapper
    resp = resource(*args, **kwargs)
  File "/home/zawar/Workspace/jwtFlask/myvenv/lib/python3.6/site-packages/flask/views.py", line 89, in view
    return self.dispatch_request(*args, **kwargs)
  File "/home/zawar/Workspace/jwtFlask/myvenv/lib/python3.6/site-packages/flask_restful/__init__.py", line 573, in dispatch_request
    resp = meth(*args, **kwargs)
  File "/home/zawar/Workspace/jwtFlask/services/resources.py", line 28, in post
    response={'message':'User created {'.format(data['username']),
ValueError: Single '{' encountered in format string
signup user
Traceback (most recent call last):
  File "/home/zawar/Workspace/jwtFlask/myvenv/lib/python3.6/site-packages/flask/app.py", line 2463, in __call__
    return self.wsgi_app(environ, start_response)
  File "/home/zawar/Workspace/jwtFlask/myvenv/lib/python3.6/site-packages/flask/app.py", line 2449, in wsgi_app
    response = self.handle_exception(e)
  File "/home/zawar/Workspace/jwtFlask/myvenv/lib/python3.6/site-packages/flask_restful/__init__.py", line 269, in error_router
    return original_handler(e)
  File "/home/zawar/Workspace/jwtFlask/myvenv/lib/python3.6/site-packages/flask/app.py", line 1866, in handle_exception
    reraise(exc_type, exc_value, tb)
  File "/home/zawar/Workspace/jwtFlask/myvenv/lib/python3.6/site-packages/flask/_compat.py", line 38, in reraise
    raise value.with_traceback(tb)
  File "/home/zawar/Workspace/jwtFlask/myvenv/lib/python3.6/site-packages/flask/app.py", line 2446, in wsgi_app
    response = self.full_dispatch_request()
  File "/home/zawar/Workspace/jwtFlask/myvenv/lib/python3.6/site-packages/flask/app.py", line 1951, in full_dispatch_request
    rv = self.handle_user_exception(e)
  File "/home/zawar/Workspace/jwtFlask/myvenv/lib/python3.6/site-packages/flask_restful/__init__.py", line 269, in error_router
    return original_handler(e)
  File "/home/zawar/Workspace/jwtFlask/myvenv/lib/python3.6/site-packages/flask/app.py", line 1820, in handle_user_exception
    reraise(exc_type, exc_value, tb)
  File "/home/zawar/Workspace/jwtFlask/myvenv/lib/python3.6/site-packages/flask/_compat.py", line 38, in reraise
    raise value.with_traceback(tb)
  File "/home/zawar/Workspace/jwtFlask/myvenv/lib/python3.6/site-packages/flask/app.py", line 1949, in full_dispatch_request
    rv = self.dispatch_request()
  File "/home/zawar/Workspace/jwtFlask/myvenv/lib/python3.6/site-packages/flask/app.py", line 1935, in dispatch_request
    return self.view_functions[rule.endpoint](**req.view_args)
  File "/home/zawar/Workspace/jwtFlask/myvenv/lib/python3.6/site-packages/flask_restful/__init__.py", line 458, in wrapper
    resp = resource(*args, **kwargs)
  File "/home/zawar/Workspace/jwtFlask/myvenv/lib/python3.6/site-packages/flask/views.py", line 89, in view
    return self.dispatch_request(*args, **kwargs)
  File "/home/zawar/Workspace/jwtFlask/myvenv/lib/python3.6/site-packages/flask_restful/__init__.py", line 573, in dispatch_request
    resp = meth(*args, **kwargs)
  File "/home/zawar/Workspace/jwtFlask/services/resources.py", line 28, in post
    response={'message':'User created {'.format(data['username']),
ValueError: Single '{' encountered in format string
signup user
Traceback (most recent call last):
  File "/home/zawar/Workspace/jwtFlask/myvenv/lib/python3.6/site-packages/flask/app.py", line 2463, in __call__
    return self.wsgi_app(environ, start_response)
  File "/home/zawar/Workspace/jwtFlask/myvenv/lib/python3.6/site-packages/flask/app.py", line 2449, in wsgi_app
    response = self.handle_exception(e)
  File "/home/zawar/Workspace/jwtFlask/myvenv/lib/python3.6/site-packages/flask_restful/__init__.py", line 269, in error_router
    return original_handler(e)
  File "/home/zawar/Workspace/jwtFlask/myvenv/lib/python3.6/site-packages/flask/app.py", line 1866, in handle_exception
    reraise(exc_type, exc_value, tb)
  File "/home/zawar/Workspace/jwtFlask/myvenv/lib/python3.6/site-packages/flask/_compat.py", line 38, in reraise
    raise value.with_traceback(tb)
  File "/home/zawar/Workspace/jwtFlask/myvenv/lib/python3.6/site-packages/flask/app.py", line 2446, in wsgi_app
    response = self.full_dispatch_request()
  File "/home/zawar/Workspace/jwtFlask/myvenv/lib/python3.6/site-packages/flask/app.py", line 1951, in full_dispatch_request
    rv = self.handle_user_exception(e)
  File "/home/zawar/Workspace/jwtFlask/myvenv/lib/python3.6/site-packages/flask_restful/__init__.py", line 269, in error_router
    return original_handler(e)
  File "/home/zawar/Workspace/jwtFlask/myvenv/lib/python3.6/site-packages/flask/app.py", line 1820, in handle_user_exception
    reraise(exc_type, exc_value, tb)
  File "/home/zawar/Workspace/jwtFlask/myvenv/lib/python3.6/site-packages/flask/_compat.py", line 38, in reraise
    raise value.with_traceback(tb)
  File "/home/zawar/Workspace/jwtFlask/myvenv/lib/python3.6/site-packages/flask/app.py", line 1949, in full_dispatch_request
    rv = self.dispatch_request()
  File "/home/zawar/Workspace/jwtFlask/myvenv/lib/python3.6/site-packages/flask/app.py", line 1935, in dispatch_request
    return self.view_functions[rule.endpoint](**req.view_args)
  File "/home/zawar/Workspace/jwtFlask/myvenv/lib/python3.6/site-packages/flask_restful/__init__.py", line 458, in wrapper
    resp = resource(*args, **kwargs)
  File "/home/zawar/Workspace/jwtFlask/myvenv/lib/python3.6/site-packages/flask/views.py", line 89, in view
    return self.dispatch_request(*args, **kwargs)
  File "/home/zawar/Workspace/jwtFlask/myvenv/lib/python3.6/site-packages/flask_restful/__init__.py", line 573, in dispatch_request
    resp = meth(*args, **kwargs)
  File "/home/zawar/Workspace/jwtFlask/services/resources.py", line 28, in post
    response={'message':'User created {'.format(data['username']),
ValueError: Single '{' encountered in format string
signup user
Traceback (most recent call last):
  File "/home/zawar/Workspace/jwtFlask/myvenv/lib/python3.6/site-packages/flask/app.py", line 2463, in __call__
    return self.wsgi_app(environ, start_response)
  File "/home/zawar/Workspace/jwtFlask/myvenv/lib/python3.6/site-packages/flask/app.py", line 2449, in wsgi_app
    response = self.handle_exception(e)
  File "/home/zawar/Workspace/jwtFlask/myvenv/lib/python3.6/site-packages/flask_restful/__init__.py", line 269, in error_router
    return original_handler(e)
  File "/home/zawar/Workspace/jwtFlask/myvenv/lib/python3.6/site-packages/flask/app.py", line 1866, in handle_exception
    reraise(exc_type, exc_value, tb)
  File "/home/zawar/Workspace/jwtFlask/myvenv/lib/python3.6/site-packages/flask/_compat.py", line 38, in reraise
    raise value.with_traceback(tb)
  File "/home/zawar/Workspace/jwtFlask/myvenv/lib/python3.6/site-packages/flask/app.py", line 2446, in wsgi_app
    response = self.full_dispatch_request()
  File "/home/zawar/Workspace/jwtFlask/myvenv/lib/python3.6/site-packages/flask/app.py", line 1951, in full_dispatch_request
    rv = self.handle_user_exception(e)
  File "/home/zawar/Workspace/jwtFlask/myvenv/lib/python3.6/site-packages/flask_restful/__init__.py", line 269, in error_router
    return original_handler(e)
  File "/home/zawar/Workspace/jwtFlask/myvenv/lib/python3.6/site-packages/flask/app.py", line 1820, in handle_user_exception
    reraise(exc_type, exc_value, tb)
  File "/home/zawar/Workspace/jwtFlask/myvenv/lib/python3.6/site-packages/flask/_compat.py", line 38, in reraise
    raise value.with_traceback(tb)
  File "/home/zawar/Workspace/jwtFlask/myvenv/lib/python3.6/site-packages/flask/app.py", line 1949, in full_dispatch_request
    rv = self.dispatch_request()
  File "/home/zawar/Workspace/jwtFlask/myvenv/lib/python3.6/site-packages/flask/app.py", line 1935, in dispatch_request
    return self.view_functions[rule.endpoint](**req.view_args)
  File "/home/zawar/Workspace/jwtFlask/myvenv/lib/python3.6/site-packages/flask_restful/__init__.py", line 458, in wrapper
    resp = resource(*args, **kwargs)
  File "/home/zawar/Workspace/jwtFlask/myvenv/lib/python3.6/site-packages/flask/views.py", line 89, in view
    return self.dispatch_request(*args, **kwargs)
  File "/home/zawar/Workspace/jwtFlask/myvenv/lib/python3.6/site-packages/flask_restful/__init__.py", line 573, in dispatch_request
    resp = meth(*args, **kwargs)
  File "/home/zawar/Workspace/jwtFlask/services/resources.py", line 28, in post
    response={'message':'User created {'.format(data['username']),
ValueError: Single '{' encountered in format string
signup user
Traceback (most recent call last):
  File "/home/zawar/Workspace/jwtFlask/myvenv/lib/python3.6/site-packages/flask/app.py", line 2463, in __call__
    return self.wsgi_app(environ, start_response)
  File "/home/zawar/Workspace/jwtFlask/myvenv/lib/python3.6/site-packages/flask/app.py", line 2449, in wsgi_app
    response = self.handle_exception(e)
  File "/home/zawar/Workspace/jwtFlask/myvenv/lib/python3.6/site-packages/flask_restful/__init__.py", line 269, in error_router
    return original_handler(e)
  File "/home/zawar/Workspace/jwtFlask/myvenv/lib/python3.6/site-packages/flask/app.py", line 1866, in handle_exception
    reraise(exc_type, exc_value, tb)
  File "/home/zawar/Workspace/jwtFlask/myvenv/lib/python3.6/site-packages/flask/_compat.py", line 38, in reraise
    raise value.with_traceback(tb)
  File "/home/zawar/Workspace/jwtFlask/myvenv/lib/python3.6/site-packages/flask/app.py", line 2446, in wsgi_app
    response = self.full_dispatch_request()
  File "/home/zawar/Workspace/jwtFlask/myvenv/lib/python3.6/site-packages/flask/app.py", line 1951, in full_dispatch_request
    rv = self.handle_user_exception(e)
  File "/home/zawar/Workspace/jwtFlask/myvenv/lib/python3.6/site-packages/flask_restful/__init__.py", line 269, in error_router
    return original_handler(e)
  File "/home/zawar/Workspace/jwtFlask/myvenv/lib/python3.6/site-packages/flask/app.py", line 1820, in handle_user_exception
    reraise(exc_type, exc_value, tb)
  File "/home/zawar/Workspace/jwtFlask/myvenv/lib/python3.6/site-packages/flask/_compat.py", line 38, in reraise
    raise value.with_traceback(tb)
  File "/home/zawar/Workspace/jwtFlask/myvenv/lib/python3.6/site-packages/flask/app.py", line 1949, in full_dispatch_request
    rv = self.dispatch_request()
  File "/home/zawar/Workspace/jwtFlask/myvenv/lib/python3.6/site-packages/flask/app.py", line 1935, in dispatch_request
    return self.view_functions[rule.endpoint](**req.view_args)
  File "/home/zawar/Workspace/jwtFlask/myvenv/lib/python3.6/site-packages/flask_restful/__init__.py", line 458, in wrapper
    resp = resource(*args, **kwargs)
  File "/home/zawar/Workspace/jwtFlask/myvenv/lib/python3.6/site-packages/flask/views.py", line 89, in view
    return self.dispatch_request(*args, **kwargs)
  File "/home/zawar/Workspace/jwtFlask/myvenv/lib/python3.6/site-packages/flask_restful/__init__.py", line 573, in dispatch_request
    resp = meth(*args, **kwargs)
  File "/home/zawar/Workspace/jwtFlask/services/resources.py", line 28, in post
    response={'message':'User created {'.format(data['username']),
ValueError: Single '{' encountered in format string
signup user
Traceback (most recent call last):
  File "/home/zawar/Workspace/jwtFlask/myvenv/lib/python3.6/site-packages/flask/app.py", line 2463, in __call__
    return self.wsgi_app(environ, start_response)
  File "/home/zawar/Workspace/jwtFlask/myvenv/lib/python3.6/site-packages/flask/app.py", line 2449, in wsgi_app
    response = self.handle_exception(e)
  File "/home/zawar/Workspace/jwtFlask/myvenv/lib/python3.6/site-packages/flask_restful/__init__.py", line 269, in error_router
    return original_handler(e)
  File "/home/zawar/Workspace/jwtFlask/myvenv/lib/python3.6/site-packages/flask/app.py", line 1866, in handle_exception
    reraise(exc_type, exc_value, tb)
  File "/home/zawar/Workspace/jwtFlask/myvenv/lib/python3.6/site-packages/flask/_compat.py", line 38, in reraise
    raise value.with_traceback(tb)
  File "/home/zawar/Workspace/jwtFlask/myvenv/lib/python3.6/site-packages/flask/app.py", line 2446, in wsgi_app
    response = self.full_dispatch_request()
  File "/home/zawar/Workspace/jwtFlask/myvenv/lib/python3.6/site-packages/flask/app.py", line 1951, in full_dispatch_request
    rv = self.handle_user_exception(e)
  File "/home/zawar/Workspace/jwtFlask/myvenv/lib/python3.6/site-packages/flask_restful/__init__.py", line 269, in error_router
    return original_handler(e)
  File "/home/zawar/Workspace/jwtFlask/myvenv/lib/python3.6/site-packages/flask/app.py", line 1820, in handle_user_exception
    reraise(exc_type, exc_value, tb)
  File "/home/zawar/Workspace/jwtFlask/myvenv/lib/python3.6/site-packages/flask/_compat.py", line 38, in reraise
    raise value.with_traceback(tb)
  File "/home/zawar/Workspace/jwtFlask/myvenv/lib/python3.6/site-packages/flask/app.py", line 1949, in full_dispatch_request
    rv = self.dispatch_request()
  File "/home/zawar/Workspace/jwtFlask/myvenv/lib/python3.6/site-packages/flask/app.py", line 1935, in dispatch_request
    return self.view_functions[rule.endpoint](**req.view_args)
  File "/home/zawar/Workspace/jwtFlask/myvenv/lib/python3.6/site-packages/flask_restful/__init__.py", line 458, in wrapper
    resp = resource(*args, **kwargs)
  File "/home/zawar/Workspace/jwtFlask/myvenv/lib/python3.6/site-packages/flask/views.py", line 89, in view
    return self.dispatch_request(*args, **kwargs)
  File "/home/zawar/Workspace/jwtFlask/myvenv/lib/python3.6/site-packages/flask_restful/__init__.py", line 573, in dispatch_request
    resp = meth(*args, **kwargs)
  File "/home/zawar/Workspace/jwtFlask/services/resources.py", line 28, in post
    response={'message':'User created {'.format(data['username']),
ValueError: Single '{' encountered in format string
signup user
Traceback (most recent call last):
  File "/home/zawar/Workspace/jwtFlask/myvenv/lib/python3.6/site-packages/flask/app.py", line 2463, in __call__
    return self.wsgi_app(environ, start_response)
  File "/home/zawar/Workspace/jwtFlask/myvenv/lib/python3.6/site-packages/flask/app.py", line 2449, in wsgi_app
    response = self.handle_exception(e)
  File "/home/zawar/Workspace/jwtFlask/myvenv/lib/python3.6/site-packages/flask_restful/__init__.py", line 269, in error_router
    return original_handler(e)
  File "/home/zawar/Workspace/jwtFlask/myvenv/lib/python3.6/site-packages/flask/app.py", line 1866, in handle_exception
    reraise(exc_type, exc_value, tb)
  File "/home/zawar/Workspace/jwtFlask/myvenv/lib/python3.6/site-packages/flask/_compat.py", line 38, in reraise
    raise value.with_traceback(tb)
  File "/home/zawar/Workspace/jwtFlask/myvenv/lib/python3.6/site-packages/flask/app.py", line 2446, in wsgi_app
    response = self.full_dispatch_request()
  File "/home/zawar/Workspace/jwtFlask/myvenv/lib/python3.6/site-packages/flask/app.py", line 1951, in full_dispatch_request
    rv = self.handle_user_exception(e)
  File "/home/zawar/Workspace/jwtFlask/myvenv/lib/python3.6/site-packages/flask_restful/__init__.py", line 269, in error_router
    return original_handler(e)
  File "/home/zawar/Workspace/jwtFlask/myvenv/lib/python3.6/site-packages/flask/app.py", line 1820, in handle_user_exception
    reraise(exc_type, exc_value, tb)
  File "/home/zawar/Workspace/jwtFlask/myvenv/lib/python3.6/site-packages/flask/_compat.py", line 38, in reraise
    raise value.with_traceback(tb)
  File "/home/zawar/Workspace/jwtFlask/myvenv/lib/python3.6/site-packages/flask/app.py", line 1949, in full_dispatch_request
    rv = self.dispatch_request()
  File "/home/zawar/Workspace/jwtFlask/myvenv/lib/python3.6/site-packages/flask/app.py", line 1935, in dispatch_request
    return self.view_functions[rule.endpoint](**req.view_args)
  File "/home/zawar/Workspace/jwtFlask/myvenv/lib/python3.6/site-packages/flask_restful/__init__.py", line 458, in wrapper
    resp = resource(*args, **kwargs)
  File "/home/zawar/Workspace/jwtFlask/myvenv/lib/python3.6/site-packages/flask/views.py", line 89, in view
    return self.dispatch_request(*args, **kwargs)
  File "/home/zawar/Workspace/jwtFlask/myvenv/lib/python3.6/site-packages/flask_restful/__init__.py", line 573, in dispatch_request
    resp = meth(*args, **kwargs)
  File "/home/zawar/Workspace/jwtFlask/services/resources.py", line 28, in post
    response={'message':'User created {'.format(data['username']),
ValueError: Single '{' encountered in format string
signup user
Traceback (most recent call last):
  File "/home/zawar/Workspace/jwtFlask/myvenv/lib/python3.6/site-packages/flask/app.py", line 2463, in __call__
    return self.wsgi_app(environ, start_response)
  File "/home/zawar/Workspace/jwtFlask/myvenv/lib/python3.6/site-packages/flask/app.py", line 2449, in wsgi_app
    response = self.handle_exception(e)
  File "/home/zawar/Workspace/jwtFlask/myvenv/lib/python3.6/site-packages/flask_restful/__init__.py", line 269, in error_router
    return original_handler(e)
  File "/home/zawar/Workspace/jwtFlask/myvenv/lib/python3.6/site-packages/flask/app.py", line 1866, in handle_exception
    reraise(exc_type, exc_value, tb)
  File "/home/zawar/Workspace/jwtFlask/myvenv/lib/python3.6/site-packages/flask/_compat.py", line 38, in reraise
    raise value.with_traceback(tb)
  File "/home/zawar/Workspace/jwtFlask/myvenv/lib/python3.6/site-packages/flask/app.py", line 2446, in wsgi_app
    response = self.full_dispatch_request()
  File "/home/zawar/Workspace/jwtFlask/myvenv/lib/python3.6/site-packages/flask/app.py", line 1951, in full_dispatch_request
    rv = self.handle_user_exception(e)
  File "/home/zawar/Workspace/jwtFlask/myvenv/lib/python3.6/site-packages/flask_restful/__init__.py", line 269, in error_router
    return original_handler(e)
  File "/home/zawar/Workspace/jwtFlask/myvenv/lib/python3.6/site-packages/flask/app.py", line 1820, in handle_user_exception
    reraise(exc_type, exc_value, tb)
  File "/home/zawar/Workspace/jwtFlask/myvenv/lib/python3.6/site-packages/flask/_compat.py", line 38, in reraise
    raise value.with_traceback(tb)
  File "/home/zawar/Workspace/jwtFlask/myvenv/lib/python3.6/site-packages/flask/app.py", line 1949, in full_dispatch_request
    rv = self.dispatch_request()
  File "/home/zawar/Workspace/jwtFlask/myvenv/lib/python3.6/site-packages/flask/app.py", line 1935, in dispatch_request
    return self.view_functions[rule.endpoint](**req.view_args)
  File "/home/zawar/Workspace/jwtFlask/myvenv/lib/python3.6/site-packages/flask_restful/__init__.py", line 458, in wrapper
    resp = resource(*args, **kwargs)
  File "/home/zawar/Workspace/jwtFlask/myvenv/lib/python3.6/site-packages/flask/views.py", line 89, in view
    return self.dispatch_request(*args, **kwargs)
  File "/home/zawar/Workspace/jwtFlask/myvenv/lib/python3.6/site-packages/flask_restful/__init__.py", line 573, in dispatch_request
    resp = meth(*args, **kwargs)
  File "/home/zawar/Workspace/jwtFlask/services/resources.py", line 28, in post
    response={'message':'User created {'.format(data['username']),
ValueError: Single '{' encountered in format string
signup user
Traceback (most recent call last):
  File "/home/zawar/Workspace/jwtFlask/myvenv/lib/python3.6/site-packages/flask/app.py", line 2463, in __call__
    return self.wsgi_app(environ, start_response)
  File "/home/zawar/Workspace/jwtFlask/myvenv/lib/python3.6/site-packages/flask/app.py", line 2449, in wsgi_app
    response = self.handle_exception(e)
  File "/home/zawar/Workspace/jwtFlask/myvenv/lib/python3.6/site-packages/flask_restful/__init__.py", line 269, in error_router
    return original_handler(e)
  File "/home/zawar/Workspace/jwtFlask/myvenv/lib/python3.6/site-packages/flask/app.py", line 1866, in handle_exception
    reraise(exc_type, exc_value, tb)
  File "/home/zawar/Workspace/jwtFlask/myvenv/lib/python3.6/site-packages/flask/_compat.py", line 38, in reraise
    raise value.with_traceback(tb)
  File "/home/zawar/Workspace/jwtFlask/myvenv/lib/python3.6/site-packages/flask/app.py", line 2446, in wsgi_app
    response = self.full_dispatch_request()
  File "/home/zawar/Workspace/jwtFlask/myvenv/lib/python3.6/site-packages/flask/app.py", line 1951, in full_dispatch_request
    rv = self.handle_user_exception(e)
  File "/home/zawar/Workspace/jwtFlask/myvenv/lib/python3.6/site-packages/flask_restful/__init__.py", line 269, in error_router
    return original_handler(e)
  File "/home/zawar/Workspace/jwtFlask/myvenv/lib/python3.6/site-packages/flask/app.py", line 1820, in handle_user_exception
    reraise(exc_type, exc_value, tb)
  File "/home/zawar/Workspace/jwtFlask/myvenv/lib/python3.6/site-packages/flask/_compat.py", line 38, in reraise
    raise value.with_traceback(tb)
  File "/home/zawar/Workspace/jwtFlask/myvenv/lib/python3.6/site-packages/flask/app.py", line 1949, in full_dispatch_request
    rv = self.dispatch_request()
  File "/home/zawar/Workspace/jwtFlask/myvenv/lib/python3.6/site-packages/flask/app.py", line 1935, in dispatch_request
    return self.view_functions[rule.endpoint](**req.view_args)
  File "/home/zawar/Workspace/jwtFlask/myvenv/lib/python3.6/site-packages/flask_restful/__init__.py", line 458, in wrapper
    resp = resource(*args, **kwargs)
  File "/home/zawar/Workspace/jwtFlask/myvenv/lib/python3.6/site-packages/flask/views.py", line 89, in view
    return self.dispatch_request(*args, **kwargs)
  File "/home/zawar/Workspace/jwtFlask/myvenv/lib/python3.6/site-packages/flask_restful/__init__.py", line 573, in dispatch_request
    resp = meth(*args, **kwargs)
  File "/home/zawar/Workspace/jwtFlask/services/resources.py", line 28, in post
    response={'message':'User created {'.format(data['username']),
ValueError: Single '{' encountered in format string
signup user
Traceback (most recent call last):
  File "/home/zawar/Workspace/jwtFlask/myvenv/lib/python3.6/site-packages/flask/app.py", line 2463, in __call__
    return self.wsgi_app(environ, start_response)
  File "/home/zawar/Workspace/jwtFlask/myvenv/lib/python3.6/site-packages/flask/app.py", line 2449, in wsgi_app
    response = self.handle_exception(e)
  File "/home/zawar/Workspace/jwtFlask/myvenv/lib/python3.6/site-packages/flask_restful/__init__.py", line 269, in error_router
    return original_handler(e)
  File "/home/zawar/Workspace/jwtFlask/myvenv/lib/python3.6/site-packages/flask/app.py", line 1866, in handle_exception
    reraise(exc_type, exc_value, tb)
  File "/home/zawar/Workspace/jwtFlask/myvenv/lib/python3.6/site-packages/flask/_compat.py", line 38, in reraise
    raise value.with_traceback(tb)
  File "/home/zawar/Workspace/jwtFlask/myvenv/lib/python3.6/site-packages/flask/app.py", line 2446, in wsgi_app
    response = self.full_dispatch_request()
  File "/home/zawar/Workspace/jwtFlask/myvenv/lib/python3.6/site-packages/flask/app.py", line 1951, in full_dispatch_request
    rv = self.handle_user_exception(e)
  File "/home/zawar/Workspace/jwtFlask/myvenv/lib/python3.6/site-packages/flask_restful/__init__.py", line 269, in error_router
    return original_handler(e)
  File "/home/zawar/Workspace/jwtFlask/myvenv/lib/python3.6/site-packages/flask/app.py", line 1820, in handle_user_exception
    reraise(exc_type, exc_value, tb)
  File "/home/zawar/Workspace/jwtFlask/myvenv/lib/python3.6/site-packages/flask/_compat.py", line 38, in reraise
    raise value.with_traceback(tb)
  File "/home/zawar/Workspace/jwtFlask/myvenv/lib/python3.6/site-packages/flask/app.py", line 1949, in full_dispatch_request
    rv = self.dispatch_request()
  File "/home/zawar/Workspace/jwtFlask/myvenv/lib/python3.6/site-packages/flask/app.py", line 1935, in dispatch_request
    return self.view_functions[rule.endpoint](**req.view_args)
  File "/home/zawar/Workspace/jwtFlask/myvenv/lib/python3.6/site-packages/flask_restful/__init__.py", line 458, in wrapper
    resp = resource(*args, **kwargs)
  File "/home/zawar/Workspace/jwtFlask/myvenv/lib/python3.6/site-packages/flask/views.py", line 89, in view
    return self.dispatch_request(*args, **kwargs)
  File "/home/zawar/Workspace/jwtFlask/myvenv/lib/python3.6/site-packages/flask_restful/__init__.py", line 573, in dispatch_request
    resp = meth(*args, **kwargs)
  File "/home/zawar/Workspace/jwtFlask/services/resources.py", line 28, in post
    response={'message':'User created {'.format(data['username']),
ValueError: Single '{' encountered in format string
signup user
Traceback (most recent call last):
  File "/home/zawar/Workspace/jwtFlask/myvenv/lib/python3.6/site-packages/flask/app.py", line 2463, in __call__
    return self.wsgi_app(environ, start_response)
  File "/home/zawar/Workspace/jwtFlask/myvenv/lib/python3.6/site-packages/flask/app.py", line 2449, in wsgi_app
    response = self.handle_exception(e)
  File "/home/zawar/Workspace/jwtFlask/myvenv/lib/python3.6/site-packages/flask_restful/__init__.py", line 269, in error_router
    return original_handler(e)
  File "/home/zawar/Workspace/jwtFlask/myvenv/lib/python3.6/site-packages/flask/app.py", line 1866, in handle_exception
    reraise(exc_type, exc_value, tb)
  File "/home/zawar/Workspace/jwtFlask/myvenv/lib/python3.6/site-packages/flask/_compat.py", line 38, in reraise
    raise value.with_traceback(tb)
  File "/home/zawar/Workspace/jwtFlask/myvenv/lib/python3.6/site-packages/flask/app.py", line 2446, in wsgi_app
    response = self.full_dispatch_request()
  File "/home/zawar/Workspace/jwtFlask/myvenv/lib/python3.6/site-packages/flask/app.py", line 1951, in full_dispatch_request
    rv = self.handle_user_exception(e)
  File "/home/zawar/Workspace/jwtFlask/myvenv/lib/python3.6/site-packages/flask_restful/__init__.py", line 269, in error_router
    return original_handler(e)
  File "/home/zawar/Workspace/jwtFlask/myvenv/lib/python3.6/site-packages/flask/app.py", line 1820, in handle_user_exception
    reraise(exc_type, exc_value, tb)
  File "/home/zawar/Workspace/jwtFlask/myvenv/lib/python3.6/site-packages/flask/_compat.py", line 38, in reraise
    raise value.with_traceback(tb)
  File "/home/zawar/Workspace/jwtFlask/myvenv/lib/python3.6/site-packages/flask/app.py", line 1949, in full_dispatch_request
    rv = self.dispatch_request()
  File "/home/zawar/Workspace/jwtFlask/myvenv/lib/python3.6/site-packages/flask/app.py", line 1935, in dispatch_request
    return self.view_functions[rule.endpoint](**req.view_args)
  File "/home/zawar/Workspace/jwtFlask/myvenv/lib/python3.6/site-packages/flask_restful/__init__.py", line 458, in wrapper
    resp = resource(*args, **kwargs)
  File "/home/zawar/Workspace/jwtFlask/myvenv/lib/python3.6/site-packages/flask/views.py", line 89, in view
    return self.dispatch_request(*args, **kwargs)
  File "/home/zawar/Workspace/jwtFlask/myvenv/lib/python3.6/site-packages/flask_restful/__init__.py", line 573, in dispatch_request
    resp = meth(*args, **kwargs)
  File "/home/zawar/Workspace/jwtFlask/services/resources.py", line 28, in post
    response={'message':'User created {'.format(data['username']),
ValueError: Single '{' encountered in format string
signup user
Traceback (most recent call last):
  File "/home/zawar/Workspace/jwtFlask/myvenv/lib/python3.6/site-packages/flask/app.py", line 2463, in __call__
    return self.wsgi_app(environ, start_response)
  File "/home/zawar/Workspace/jwtFlask/myvenv/lib/python3.6/site-packages/flask/app.py", line 2449, in wsgi_app
    response = self.handle_exception(e)
  File "/home/zawar/Workspace/jwtFlask/myvenv/lib/python3.6/site-packages/flask_restful/__init__.py", line 269, in error_router
    return original_handler(e)
  File "/home/zawar/Workspace/jwtFlask/myvenv/lib/python3.6/site-packages/flask/app.py", line 1866, in handle_exception
    reraise(exc_type, exc_value, tb)
  File "/home/zawar/Workspace/jwtFlask/myvenv/lib/python3.6/site-packages/flask/_compat.py", line 38, in reraise
    raise value.with_traceback(tb)
  File "/home/zawar/Workspace/jwtFlask/myvenv/lib/python3.6/site-packages/flask/app.py", line 2446, in wsgi_app
    response = self.full_dispatch_request()
  File "/home/zawar/Workspace/jwtFlask/myvenv/lib/python3.6/site-packages/flask/app.py", line 1951, in full_dispatch_request
    rv = self.handle_user_exception(e)
  File "/home/zawar/Workspace/jwtFlask/myvenv/lib/python3.6/site-packages/flask_restful/__init__.py", line 269, in error_router
    return original_handler(e)
  File "/home/zawar/Workspace/jwtFlask/myvenv/lib/python3.6/site-packages/flask/app.py", line 1820, in handle_user_exception
    reraise(exc_type, exc_value, tb)
  File "/home/zawar/Workspace/jwtFlask/myvenv/lib/python3.6/site-packages/flask/_compat.py", line 38, in reraise
    raise value.with_traceback(tb)
  File "/home/zawar/Workspace/jwtFlask/myvenv/lib/python3.6/site-packages/flask/app.py", line 1949, in full_dispatch_request
    rv = self.dispatch_request()
  File "/home/zawar/Workspace/jwtFlask/myvenv/lib/python3.6/site-packages/flask/app.py", line 1935, in dispatch_request
    return self.view_functions[rule.endpoint](**req.view_args)
  File "/home/zawar/Workspace/jwtFlask/myvenv/lib/python3.6/site-packages/flask_restful/__init__.py", line 458, in wrapper
    resp = resource(*args, **kwargs)
  File "/home/zawar/Workspace/jwtFlask/myvenv/lib/python3.6/site-packages/flask/views.py", line 89, in view
    return self.dispatch_request(*args, **kwargs)
  File "/home/zawar/Workspace/jwtFlask/myvenv/lib/python3.6/site-packages/flask_restful/__init__.py", line 573, in dispatch_request
    resp = meth(*args, **kwargs)
  File "/home/zawar/Workspace/jwtFlask/services/resources.py", line 28, in post
    response={'message':'User created {'.format(data['username']),
ValueError: Single '{' encountered in format string
signup user
Traceback (most recent call last):
  File "/home/zawar/Workspace/jwtFlask/myvenv/lib/python3.6/site-packages/flask/app.py", line 2463, in __call__
    return self.wsgi_app(environ, start_response)
  File "/home/zawar/Workspace/jwtFlask/myvenv/lib/python3.6/site-packages/flask/app.py", line 2449, in wsgi_app
    response = self.handle_exception(e)
  File "/home/zawar/Workspace/jwtFlask/myvenv/lib/python3.6/site-packages/flask_restful/__init__.py", line 269, in error_router
    return original_handler(e)
  File "/home/zawar/Workspace/jwtFlask/myvenv/lib/python3.6/site-packages/flask/app.py", line 1866, in handle_exception
    reraise(exc_type, exc_value, tb)
  File "/home/zawar/Workspace/jwtFlask/myvenv/lib/python3.6/site-packages/flask/_compat.py", line 38, in reraise
    raise value.with_traceback(tb)
  File "/home/zawar/Workspace/jwtFlask/myvenv/lib/python3.6/site-packages/flask/app.py", line 2446, in wsgi_app
    response = self.full_dispatch_request()
  File "/home/zawar/Workspace/jwtFlask/myvenv/lib/python3.6/site-packages/flask/app.py", line 1951, in full_dispatch_request
    rv = self.handle_user_exception(e)
  File "/home/zawar/Workspace/jwtFlask/myvenv/lib/python3.6/site-packages/flask_restful/__init__.py", line 269, in error_router
    return original_handler(e)
  File "/home/zawar/Workspace/jwtFlask/myvenv/lib/python3.6/site-packages/flask/app.py", line 1820, in handle_user_exception
    reraise(exc_type, exc_value, tb)
  File "/home/zawar/Workspace/jwtFlask/myvenv/lib/python3.6/site-packages/flask/_compat.py", line 38, in reraise
    raise value.with_traceback(tb)
  File "/home/zawar/Workspace/jwtFlask/myvenv/lib/python3.6/site-packages/flask/app.py", line 1949, in full_dispatch_request
    rv = self.dispatch_request()
  File "/home/zawar/Workspace/jwtFlask/myvenv/lib/python3.6/site-packages/flask/app.py", line 1935, in dispatch_request
    return self.view_functions[rule.endpoint](**req.view_args)
  File "/home/zawar/Workspace/jwtFlask/myvenv/lib/python3.6/site-packages/flask_restful/__init__.py", line 458, in wrapper
    resp = resource(*args, **kwargs)
  File "/home/zawar/Workspace/jwtFlask/myvenv/lib/python3.6/site-packages/flask/views.py", line 89, in view
    return self.dispatch_request(*args, **kwargs)
  File "/home/zawar/Workspace/jwtFlask/myvenv/lib/python3.6/site-packages/flask_restful/__init__.py", line 573, in dispatch_request
    resp = meth(*args, **kwargs)
  File "/home/zawar/Workspace/jwtFlask/services/resources.py", line 28, in post
    response={'message':'User created {'.format(data['username']),
ValueError: Single '{' encountered in format string
signup user
Traceback (most recent call last):
  File "/home/zawar/Workspace/jwtFlask/myvenv/lib/python3.6/site-packages/flask/app.py", line 2463, in __call__
    return self.wsgi_app(environ, start_response)
  File "/home/zawar/Workspace/jwtFlask/myvenv/lib/python3.6/site-packages/flask/app.py", line 2449, in wsgi_app
    response = self.handle_exception(e)
  File "/home/zawar/Workspace/jwtFlask/myvenv/lib/python3.6/site-packages/flask_restful/__init__.py", line 269, in error_router
    return original_handler(e)
  File "/home/zawar/Workspace/jwtFlask/myvenv/lib/python3.6/site-packages/flask/app.py", line 1866, in handle_exception
    reraise(exc_type, exc_value, tb)
  File "/home/zawar/Workspace/jwtFlask/myvenv/lib/python3.6/site-packages/flask/_compat.py", line 38, in reraise
    raise value.with_traceback(tb)
  File "/home/zawar/Workspace/jwtFlask/myvenv/lib/python3.6/site-packages/flask/app.py", line 2446, in wsgi_app
    response = self.full_dispatch_request()
  File "/home/zawar/Workspace/jwtFlask/myvenv/lib/python3.6/site-packages/flask/app.py", line 1951, in full_dispatch_request
    rv = self.handle_user_exception(e)
  File "/home/zawar/Workspace/jwtFlask/myvenv/lib/python3.6/site-packages/flask_restful/__init__.py", line 269, in error_router
    return original_handler(e)
  File "/home/zawar/Workspace/jwtFlask/myvenv/lib/python3.6/site-packages/flask/app.py", line 1820, in handle_user_exception
    reraise(exc_type, exc_value, tb)
  File "/home/zawar/Workspace/jwtFlask/myvenv/lib/python3.6/site-packages/flask/_compat.py", line 38, in reraise
    raise value.with_traceback(tb)
  File "/home/zawar/Workspace/jwtFlask/myvenv/lib/python3.6/site-packages/flask/app.py", line 1949, in full_dispatch_request
    rv = self.dispatch_request()
  File "/home/zawar/Workspace/jwtFlask/myvenv/lib/python3.6/site-packages/flask/app.py", line 1935, in dispatch_request
    return self.view_functions[rule.endpoint](**req.view_args)
  File "/home/zawar/Workspace/jwtFlask/myvenv/lib/python3.6/site-packages/flask_restful/__init__.py", line 458, in wrapper
    resp = resource(*args, **kwargs)
  File "/home/zawar/Workspace/jwtFlask/myvenv/lib/python3.6/site-packages/flask/views.py", line 89, in view
    return self.dispatch_request(*args, **kwargs)
  File "/home/zawar/Workspace/jwtFlask/myvenv/lib/python3.6/site-packages/flask_restful/__init__.py", line 573, in dispatch_request
    resp = meth(*args, **kwargs)
  File "/home/zawar/Workspace/jwtFlask/services/resources.py", line 28, in post
    response={'message':'User created {'.format(data['username']),
ValueError: Single '{' encountered in format string
signup user
Traceback (most recent call last):
  File "/home/zawar/Workspace/jwtFlask/myvenv/lib/python3.6/site-packages/flask/app.py", line 2463, in __call__
    return self.wsgi_app(environ, start_response)
  File "/home/zawar/Workspace/jwtFlask/myvenv/lib/python3.6/site-packages/flask/app.py", line 2449, in wsgi_app
    response = self.handle_exception(e)
  File "/home/zawar/Workspace/jwtFlask/myvenv/lib/python3.6/site-packages/flask_restful/__init__.py", line 269, in error_router
    return original_handler(e)
  File "/home/zawar/Workspace/jwtFlask/myvenv/lib/python3.6/site-packages/flask/app.py", line 1866, in handle_exception
    reraise(exc_type, exc_value, tb)
  File "/home/zawar/Workspace/jwtFlask/myvenv/lib/python3.6/site-packages/flask/_compat.py", line 38, in reraise
    raise value.with_traceback(tb)
  File "/home/zawar/Workspace/jwtFlask/myvenv/lib/python3.6/site-packages/flask/app.py", line 2446, in wsgi_app
    response = self.full_dispatch_request()
  File "/home/zawar/Workspace/jwtFlask/myvenv/lib/python3.6/site-packages/flask/app.py", line 1951, in full_dispatch_request
    rv = self.handle_user_exception(e)
  File "/home/zawar/Workspace/jwtFlask/myvenv/lib/python3.6/site-packages/flask_restful/__init__.py", line 269, in error_router
    return original_handler(e)
  File "/home/zawar/Workspace/jwtFlask/myvenv/lib/python3.6/site-packages/flask/app.py", line 1820, in handle_user_exception
    reraise(exc_type, exc_value, tb)
  File "/home/zawar/Workspace/jwtFlask/myvenv/lib/python3.6/site-packages/flask/_compat.py", line 38, in reraise
    raise value.with_traceback(tb)
  File "/home/zawar/Workspace/jwtFlask/myvenv/lib/python3.6/site-packages/flask/app.py", line 1949, in full_dispatch_request
    rv = self.dispatch_request()
  File "/home/zawar/Workspace/jwtFlask/myvenv/lib/python3.6/site-packages/flask/app.py", line 1935, in dispatch_request
    return self.view_functions[rule.endpoint](**req.view_args)
  File "/home/zawar/Workspace/jwtFlask/myvenv/lib/python3.6/site-packages/flask_restful/__init__.py", line 458, in wrapper
    resp = resource(*args, **kwargs)
  File "/home/zawar/Workspace/jwtFlask/myvenv/lib/python3.6/site-packages/flask/views.py", line 89, in view
    return self.dispatch_request(*args, **kwargs)
  File "/home/zawar/Workspace/jwtFlask/myvenv/lib/python3.6/site-packages/flask_restful/__init__.py", line 573, in dispatch_request
    resp = meth(*args, **kwargs)
  File "/home/zawar/Workspace/jwtFlask/services/resources.py", line 28, in post
    response={'message':'User created {'.format(data['username']),
ValueError: Single '{' encountered in format string
 * Serving Flask app "run" (lazy loading)
 * Environment: production
   WARNING: This is a development server. Do not use it in a production deployment.
   Use a production WSGI server instead.
 * Debug mode: on
